I'm sorry, but an uncaught exception occurred.

While running game code:
  File "game/script.rpy", line 186, in script
    lb "Someone's been eating my porridge and they ate it all up!"
Exception: Sayer 'lb' is not defined.

-- Full Traceback ------------------------------------------------------------

Full traceback:
  File "game/script.rpy", line 186, in script
    lb "Someone's been eating my porridge and they ate it all up!"
  File "F:\ren\renpy-7.2.2-sdk\renpy\ast.py", line 664, in execute
    who = eval_who(self.who, self.who_fast)
  File "F:\ren\renpy-7.2.2-sdk\renpy\ast.py", line 564, in eval_who
    raise Exception("Sayer '%s' is not defined." % who.encode("utf-8"))
Exception: Sayer 'lb' is not defined.

Windows-8-6.2.9200
Ren'Py 7.2.2.491
test1 1.0
Thu Jun 06 22:07:04 2019
